<mujoco>

  <compiler assetdir="assets" />

  <compiler angle="degree" coordinate="local" inertiafromgeom="true" />
  <!-- <option gravity="0 0 -9.8"  density="1.293" viscosity="1.8e-5" > -->
  <!-- <option  gravity="0 0 -9.8" viscosity="1.8e-5" integrator="implicit" > -->
  <option gravity="0 0 -9.8" viscosity="1.8e-5" >
    <flag contact="enable"/>
  </option>

  <default>
    <motor ctrlrange="-1 1" />
    <default class="imported">
      <mesh scale="0.001 0.001 0.001" />
    </default>


    <default class="balloon">
    <geom density="0.167" fluidshape="ellipsoid" />
    </default>

    </default>

  <visual>
    <headlight diffuse="0.6 0.6 0.6" ambient="0.3 0.3 0.3" specular="0 0 0" />
    <rgba haze="0.15 0.25 0.35 1" />
    <global azimuth="-20" elevation="-20" ellipsoidinertia="true" />
  </visual>

  <asset>
    <!-- <texture type="skybox" builtin="gradient" rgb1="0. 0 0" rgb2="0 0 0" width="1" -->
      <!-- height="30720" /> -->
    <texture type="2d" name="groundplane" builtin="checker" mark="edge" rgb1="0 0 0"
      rgb2="0 0 0"
      markrgb="0.8 0.8 0.8" width="300" height="300" />
    <material name="groundplane" texture="groundplane" texuniform="true" texrepeat="5 5"
      reflectance="0.002" />
    <mesh file="BalloonBody.obj" class="imported"/>
    <mesh file="Frame.obj" class="imported"/>
    <mesh file="CarbonFiber.obj" class="imported"/>
    <mesh file="PropGuard.obj" class="imported"/>
    <mesh file="ServoMount.obj" class="imported"/>
    <mesh file="Board Mount.obj" class="imported" />
    <!-- <mesh file="House.obj" scale="0.3 0.3 0.3"/> -->

 </asset>


  <worldbody>
    <light pos="0 0 1.5" dir="0 0 -1" directional="true" />
    <geom name="floor" size="0 0 0.05" type="plane" material="groundplane" />
    <!-- <geom type="mesh" mesh="House" pos="1 1 0.1"/> -->
  </worldbody>


  <worldbody>
    <body>
      <freejoint/>
      <geom name="waypoint" type="cylinder"  rgba="0 1 0 .08" size=".3  1" pos="1 1 1"/>
    </body>
    <body gravcomp="7.2" pos="0 0 1">
      <freejoint />
      <geom name="mylar" type="mesh" mesh="BalloonBody" rgba="0.6 0 0 1" mass="1"/>
      <site name="mountBalloon1" pos="-.05 0  -0.27"/>
      <site name="mountBalloon2" pos=".05 0 -0.27"/>
      <camera name="followCamera" pos="0 -2.5 .2" euler="90 0 0" />
    </body>
    <body pos="0 0 0.73" euler="180 0 0">
      <freejoint/>
        <site name="mountGondola1" pos="-.05 0 0"/>
        <site name="mountGondola2" pos=".05 0 0"/>
        <camera name="blimpCamera" pos="0 0.08 0.03" euler="90 0 180" />
        <geom type="mesh" name="controller" mesh="Frame" euler="0 0 0" mass="5.82"/>
        <geom name="carbonFiberRod" type="mesh" mesh="CarbonFiber"  size="0.004 0.5 0.004"  mass="0.25"/>
        <body name = "m1" pos ="-0.27 -0.005 0.002">
          <geom type="mesh" mesh="ServoMount" euler="0 0 180"/>
          <body name="guard1" pos="-0.04 0 -0.008" euler="0 0 0" >
            <geom type="mesh" mesh="PropGuard" euler = "180 0 0"  mass="0.04"/>
          <joint axis="1 0 0" name="servo1" pos="0.0 0.0 0.0" range="0 180" damping="0.003" type="hinge"/>
            <body name="prop1">
              <joint axis = "1 0 0" name="propeller1" damping="0.0003" type="hinge"/>
              <geom type="ellipsoid" size="0.035 0.006 0.0001" mass="0.02"/>
              <site name="thrust1" pos="0 0 0.008" />
            </body>
          </body>
        </body>
        <body name = "m2" pos = "0.27 0.005 0.002">
          <geom type="mesh" mesh="ServoMount"  euler="0 0 0"/>
          <body name="guard2" pos="0.04 0. -0.008" euler="0 0 0">
            <geom type="mesh" mesh="PropGuard" euler = "180 0 180" mass="0.04" />
          <joint axis="1 0 0" name="servo2" pos="0.0 0.0 0.0" range="0 180" damping="0.003" type="hinge"/>
            <body name="prop2">
              <joint axis = "1 0 0" name="propeller2" damping="0.0003" type="hinge"/>
              <geom type="ellipsoid" size="0.035 0.006 0.0001"  mass="0.02"/>
              <site name="thrust2" pos="0 0 0" />
            </body>
          </body>
        </body>
        <site name="imu" pos="0 0 0" />
    </body>
    </worldbody>



  <actuator>

    <motor name="servo1" ctrllimited="true" forcerange="0 10" ctrlrange="0 4" joint="servo1" />
    <motor name="servo2" ctrllimited="true" forcerange="0 10" ctrlrange="0 4" joint="servo2" />
    <motor name="motor1" site="thrust1"  gear="0 0 7 0 0 0" ctrlrange="-2 2"/>
    <motor name="motor2" site="thrust2" gear="0 0 7 0 0 0" ctrlrange="-2 2"/>

  </actuator>



  <tendon>
    <spatial range="0 0.0001">
      <site site="mountBalloon1"/>
      <site site="mountGondola1"/>
    </spatial>

    <spatial range="0 0.0001">
      <site site="mountBalloon2"/>
      <site site="mountGondola2"/>
    </spatial>



  </tendon>

  <sensor>
    <gyro name="body_gyro" site="imu" />
    <accelerometer name="body_linacc" site="imu" />
    <framequat name="body_quat" objtype="site" objname="imu" />
  </sensor>



</mujoco>
